<?xml version="1.0"?>
<robot name="my_robot">


  <link name="base_link">
    <visual>
      <geometry>
        <box size = "0.4878 0.8382 0.0381"/>
      </geometry>
    </visual>
    <collision>
        <geometry>
        <box size = "0.4878 0.8382 0.0381"/>    
        </geometry>
    </collision>
  </link>

  <link name ="wheel_left">
    <visual>
        <geometry>
            <cylinder radius = "0.127" length = "0.0889"/>
        </geometry>
    </visual>
    <collision>
        <geometry>
            <cylinder radius = "0.127" length = "0.0889"/>
        </geometry>
    </collision>
    <inertial>
      <mass value="10"/>
      <inertia
        ixx="1.0" ixy="0.0" ixz="0.0"
        iyy="1.0" iyz="0.0"
        izz="1.0"/>    </inertial>
        <gazebo reference="wheel_left">
      <mu1 value="200.0"/>
      <mu2 value="100.0"/>
      <kp value="10000000.0" />
      <kd value="1.0" />
    </gazebo>
  </link>

  <link name ="wheel_right">
    <visual>
        <geometry>
            <cylinder radius = "0.127" length = "0.0889"/>
        </geometry>
    </visual>
    <collision>
        <geometry>
            <cylinder radius = "0.127" length = "0.0889"/>
        </geometry>
    </collision>
    <inertial>
      <mass value="10"/>
      <inertia
        ixx="1.0" ixy="0.0" ixz="0.0"
        iyy="1.0" iyz="0.0"
        izz="1.0"/>    </inertial>
        <gazebo reference="wheel_right">
      <mu1 value="200.0"/>
      <mu2 value="100.0"/>
      <kp value="10000000.0" />
      <kd value="1.0" />
    </gazebo>
  </link>


  <joint name="joint1" type="continuous">
    <parent link = "base_link"/>
    <child link = "wheel_left"/>
        <origin xyz = "0 -0.3175 0" rpy = "1.5708 0 0"/>
    <axis xyz = "0 0 1"/>
        <limit effort="10000" velocity="1000"/>    
    <joint_properties damping="1.0" friction="1.0" /> 
  </joint>


  <joint name="joint2" type="continuous">
    <parent link = "base_link"/>
    <child link = "wheel_right"/>
        <origin xyz = "0 0.3175 0" rpy = "1.5708 0 0"/>
    <axis xyz = "0 0 1"/>
        <limit effort="10000" velocity="1000"/>    
    <joint_properties damping="1.0" friction="1.0" /> 
  </joint>

 <transmission name="joint1_transmission">
    <type>transmission_interface/SimpleTransmission</type>
    <joint name="joint1">
      <hardwareInterface>
        hardware_interface/VelocityJointInterface
      </hardwareInterface>      
    </joint> 
    <actuator name="joint1_actuator">        
      <mechanicalReduction>1</mechanicalReduction>    
    </actuator> 
  </transmission>


  <transmission name="joint2_transmission">
    <type>transmission_interface/SimpleTransmission</type>
    <joint name="joint2_wheel">
      <hardwareInterface>
        hardware_interface/VelocityJointInterface
      </hardwareInterface>      
    </joint> 
    <actuator name="joint2_actuator">        
      <mechanicalReduction>1</mechanicalReduction>    
    </actuator> 
  </transmission>



  <gazebo>
    <plugin name="gazebo_ros_control" filename="libgazebo_ros_control.so">
      <robotNamespace>/</robotNamespace>
    </plugin>
  </gazebo>

</robot>